<?xml version="1.0"?>

<robot name="shuang_6" xmlns:xacro="http://ros.org/wiki/xacro">

  <!-- Define a number of dimensions using properties -->
  
  <property name="base_mesh_scale" value="1" />
  
  <property name="PI" value="3.1415926" />
  <property name="six_offset_x" value="0.09" />
  <property name="six_offset_y" value="0" />
  <property name="six_offset_z" value="0" />     

  <!-- The base xacro macro <axis xyz ="0 0 1">
     <limit effort ="100" velocity ="100">
     <safety_controller k_velocity ="10"> -->
  <macro name="shuang_6" params="parent name suffix reflect color pose ">
    <joint name="${parent}_${suffix}_${name}_joint" type="revolute">
     <axis xyz="1 0 0" />
     <origin xyz="${six_offset_x} ${six_offset_y} ${six_offset_z}" rpy="0 0 ${pose}" />
     <parent link="${parent}_link"/>
     <child link="${suffix}_${name}_link"/>
     <limit lower="${-2*PI}"  upper="${2*PI}"
             effort="30" velocity="${VELOCITY_LIMIT_SCALE*3.48}" /> <!-- alpha tested velocity and effort limits -->

      <dynamics damping="10.0" />
    <!--  <safety_controller k_position="100" k_velocity="10"
                         soft_lower_limit="${reflect*PI/4-1.5+0.15}"
                         soft_upper_limit="${reflect*PI/4+1.5-0.15}" />
       joint angle when the rising or the falling flag is activated -->
      <calibration  rising="${reflect*PI/4}" />
    </joint>

    <link name="${suffix}_${name}_link">
      <visual>
        <origin xyz="0 0 0" rpy="0 0 0" />
        <geometry>
           <mesh filename="package://shuang/meshes/l6_Link.STL" scale="${base_mesh_scale} ${base_mesh_scale} ${base_mesh_scale}" />
        </geometry>
        <material name="${color}" />
      </visual>
      <collision>
        <origin xyz="0 0 0" rpy="0 0 0" />
       <geometry>
          <mesh filename="package://shuang/meshes/l6_Link.STL" />
        </geometry>
      </collision>
    </link>
  </macro>

</robot>
