<?xml version="1.0"?>

<robot name="shuang_1" xmlns:xacro="http://ros.org/wiki/xacro">

  <!-- Define a number of dimensions using properties -->
  
  <property name="base_mesh_scale" value="1" />
  
  <property name="PI" value="3.1415" />
  <property name="one_offset_x" value="0" />
  <property name="one_offset_y" value="0.172" />
  <property name="one_offset_z" value="0.9" />     
  <property name="VELOCITY_LIMIT_SCALE" value="0.6" />

  <!-- The base xacro macro <axis xyz ="0 0 1">
     <limit effort ="100" velocity ="100">
     <safety_controller k_velocity ="10"> -->
  <macro name="shuang_1" params="parent name suffix reflect color pose ">
    <joint name="${parent}_${suffix}_${name}_joint" type="revolute">
     <axis xyz="0 0 1" />
     <origin xyz="${one_offset_x} ${reflect*one_offset_y} ${one_offset_z}" rpy="${-PI/2} ${PI/2} ${pose}" />
     <parent link="${parent}_link"/>
     <child link="${suffix}_${name}_link"/>
     <limit lower="${PI/4-3}"  upper="${PI/4+3}"
             effort="30" velocity="${VELOCITY_LIMIT_SCALE*3.48}" /> <!-- alpha tested velocity and effort limits -->

      <dynamics damping="10.0" />
    <!--  <safety_controller k_position="100" k_velocity="10"
                         soft_lower_limit="${reflect*PI/4-1.5+0.15}"
                         soft_upper_limit="${reflect*PI/4+1.5-0.15}" />
       joint angle when the rising or the falling flag is activated -->
      <calibration  rising="${reflect*PI/4}" />


    </joint>
    <transmission name="tran_${suffix}_${name}">
      <type>transmission_interface/SimpleTransmission</type>
      <joint name="${parent}_${suffix}_${name}_joint">

        <hardwareInterface>hardware_interface/PositionJointInterface</hardwareInterface>
      </joint>
      <actuator name="motor_${suffix}_${name}">

      <hardwareInterface>hardware_interface/PositionJointInterface</hardwareInterface>
      <mechanicalReduction>1</mechanicalReduction>
      </actuator>
    </transmission>


    
	 
   <!-- <xacro:transmission_block joint_name="${parent}_${suffix}_${name}_joint" trans="${suffix}_${name}" motor="${suffix}_${name}"/> -->


    <link name="${suffix}_${name}_link">
      <visual>
        <origin xyz="0 0 0" rpy="0 0 0" />
        <geometry>
           <mesh filename="package://shuang/meshes/l1_Link.STL" scale="${base_mesh_scale} ${base_mesh_scale} ${base_mesh_scale}" />
        </geometry>
        <material name="${color}" />
      </visual>
      <collision>
        <origin xyz="0 0 0" rpy="0 0 0" />
       <geometry>
          <mesh filename="package://shuang/meshes/l1_Link.STL" />
        </geometry>
      </collision>
      <inertial>
      <origin
        xyz="0.0399499465577251 -0.00179915325387669 0.0786427669335215"
        rpy="0 0 0" />
      <mass
        value="3.0910257295979" />
      <inertia
        ixx="0.0126170995781766"
        ixy="0.000295269550978695"
        ixz="-0.0055755014891478"
        iyy="0.018010156692679"
        iyz="0.00034421402351512"
        izz="0.0138131510539468" />
    </inertial>
    </link>
  </macro>
          </robot>
