<?xml version="1.0"?>

<robot name="shuang_2" xmlns:xacro="http://ros.org/wiki/xacro">

  <!-- Define a number of dimensions using properties -->
  
  <property name="base_mesh_scale" value="1" />
  
  <property name="PI" value="3.1415926" />
  <property name="two_offset_x" value="0.088" />
  <property name="two_offset_y" value="0" />
  <property name="two_offset_z" value="0.131" />     

  <!-- The base xacro macro <axis xyz ="0 0 1">
     <limit effort ="100" velocity ="100">
     <safety_controller k_velocity ="10"> -->
  <macro name="shuang_2" params="parent name suffix reflect color pose ">
    <joint name="${parent}_${suffix}_${name}_joint" type="revolute">
     <axis xyz="0 1 0" />
     <origin xyz="${two_offset_x} ${two_offset_y} ${two_offset_z}" rpy="0 ${PI/2} ${pose}" />
     <parent link="${parent}_link"/>
     <child link="${suffix}_${name}_link"/>
     <limit lower="-4"  upper="-2.2"
             effort="30" velocity="${VELOCITY_LIMIT_SCALE*3.48}" /> <!-- alpha tested velocity and effort limits -->

      <dynamics damping="10.0" 
                />
    <!--  <safety_controller k_position="100" k_velocity="10"
                         soft_lower_limit="${reflect*PI/4-1.5+0.15}"
                         soft_upper_limit="${reflect*PI/4+1.5-0.15}" />
       joint angle when the rising or the falling flag is activated -->
      <calibration  rising="${reflect*PI/4}" />

    </joint>

    <transmission name="tran_${suffix}_${name}">
      <type>transmission_interface/SimpleTransmission</type>
      <joint name="${parent}_${suffix}_${name}_joint">

      <hardwareInterface>hardware_interface/PositionJointInterface</hardwareInterface>
      </joint>
      <actuator name="motor_${suffix}_${name}">

      <hardwareInterface>hardware_interface/PositionJointInterface</hardwareInterface>
      <mechanicalReduction>1</mechanicalReduction>
      </actuator>
    </transmission>
 


    <link name="${suffix}_${name}_link">
      <visual>
        <origin xyz="0 0 0" rpy="0 0 0" />
        <geometry>
           <mesh filename="package://shuang/meshes/l2_Link.STL" scale="${base_mesh_scale} ${base_mesh_scale} ${base_mesh_scale}" />
        </geometry>
        <material name="${color}" />
      </visual>
      <collision>
        <origin xyz="0 0 0" rpy="0 0 0" />
       <geometry>
          <mesh filename="package://shuang/meshes/l2_Link.STL" />
        </geometry>
      </collision>
      <inertial>
      <origin
        xyz="0.135966081204625 0.00215309895833472 0.00782968659939631"
        rpy="0 0 0" />
      <mass
        value="5.36773036532575" />
      <inertia
        ixx="0.035221593177348"
        ixy="0.000702778836765928"
        ixz="-0.000431571577941172"
        iyy="0.0615882126675028"
        iyz="-1.87912758843142E-05"
        izz="0.0871475560954985" />
    </inertial>
    </link>
  </macro>


 

</robot>
