<?xml version="1.0"?>

<robot name="shuang_3" xmlns:xacro="http://ros.org/wiki/xacro">

  <!-- Define a number of dimensions using properties -->
  
  <property name="base_mesh_scale" value="1" />
  
  <property name="PI" value="3.1415926" />
  <property name="three_offset_x" value="0.31" />
  <property name="three_offset_y" value="0" />
  <property name="three_offset_z" value="0" />     

  <!-- The base xacro macro <axis xyz ="0 0 1">
     <limit effort ="100" velocity ="100">
     <safety_controller k_velocity ="10"> -->
  <macro name="shuang_3" params="parent name suffix reflect color pose ">
    <joint name="${parent}_${suffix}_${name}_joint" type="revolute">
     <axis xyz="0 1 0" />
     <origin xyz="${three_offset_x} ${three_offset_y} ${three_offset_z}" rpy="0 ${PI/2} ${pose}" />
     <parent link="${parent}_link"/>
     <child link="${suffix}_${name}_link"/>
     <limit lower="${-PI/2-1}"  upper="${PI/4}"
             effort="30" velocity="${VELOCITY_LIMIT_SCALE*3.48}" /> <!-- alpha tested velocity and effort limits -->

      <dynamics damping="10.0" />
    <!--  <safety_controller k_position="100" k_velocity="10"
                         soft_lower_limit="${reflect*PI/4-1.5+0.15}"
                         soft_upper_limit="${reflect*PI/4+1.5-0.15}" />
       joint angle when the rising or the falling flag is activated -->
      <calibration  rising="${reflect*PI/4}" />

    </joint>

    <transmission name="tran_${suffix}_${name}">
      <type>transmission_interface/SimpleTransmission</type>
      <joint name="${parent}_${suffix}_${name}_joint">

        <hardwareInterface>hardware_interface/PositionJointInterface</hardwareInterface>
      </joint>
      <actuator name="motor_${suffix}_${name}">

      <hardwareInterface>hardware_interface/PositionJointInterface</hardwareInterface>
      <mechanicalReduction>1</mechanicalReduction>
      </actuator>
    </transmission>

    <link name="${suffix}_${name}_link">
      <visual>
        <origin xyz="0 0 0" rpy="0 0 0" />
        <geometry>
           <mesh filename="package://shuang/meshes/l3_Link.STL" scale="${base_mesh_scale} ${base_mesh_scale} ${base_mesh_scale}" />
        </geometry>
        <material name="${color}" />
      </visual>
      <collision>
        <origin xyz="0 0 0" rpy="0 0 0" />
       <geometry>
          <mesh filename="package://shuang/meshes/l3_Link.STL" />
        </geometry>
      </collision>
      <inertial>
      <origin
        xyz="-0.0126998745500521 -0.00107939530708143 0.0179304064393622"
        rpy="0 0 0" />
      <mass
        value="2.61956491426746" />
      <inertia
        ixx="0.00729416576999638"
        ixy="2.67728162569164E-05"
        ixz="-0.000809519930358035"
        iyy="0.00901987275681055"
        iyz="-3.36572861649285E-05"
        izz="0.00812527081391672" />
    </inertial>
    </link>
  </macro>


 

</robot>
